Workbook

Sheet 통합보장 분석(전)
A1: VIP 고객님 통합보장 분석
A3: 생년월일 | C3: ="보험나이 "&DATEDIF(EDATE($A$4,-6),$F$6,"y")&"세" -> 보험나이 35세
A4: 33302 | C4: =EDATE($A$4,6) -> 33486
A6: 구 분 | C6: 회 사 명 | E6: Total | F6: =TODAY() -> 46207
C7: 보 험 종 류
A8: 계 약 | C8: 계 약 일
C9: 납 입 기 간
C10: 보 험 기 간
C11: 월보험료(원) | E11: =SUM(G11:P11) -> 0
C12: 갱신 예상보험료 | E12: =SUM(G12:P12) -> 0
C13: 총납입보험료 | E13: =SUM(G13:P13) -> 0
C14: 납입완료 | E14: =SUM(G14:P14) -> 0
C15: 납입예정 | E15: =SUM(G15:P15) -> 0
A16: 실손의료비 | C16: 질병 입원의료비 | E16: =SUM(G16:P16) -> 0
C17: 질병 통원의료비 | E17: =SUM(G17:P17) -> 0
C18: 상해 입원의료비 | E18: =SUM(G18:P18) -> 0
C19: 상해 통원의료비 | E19: =SUM(G19:P19) -> 0
A23: 3대 질병 | B23: 암 | C23: 고액암 | E23: =E24+E25+E26+E27+SUM(G23:P23) -> 0
C24: 일반암 | E24: =SUM(G24:P24) -> 0
C25: 일반암(소액·대장점막제외) | E25: =SUM(G25:P25) -> 0
C26: 일반암(소액암제외) | E26: =SUM(G26:P26) -> 0
C27: 중대한암 | E27: =SUM(G27:P27) -> 0
C28: 소액암(생식기암) | E28: =SUM(G28:P28) -> 0
C29: 소액암 | E29: =SUM(G29:P29) -> 0
C30: 수술비 | E30: =SUM(G30:P30) -> 0
C31: 항암치료/표적/중입자 | E31: =SUM(G31:P31) -> 0
C32: 암주요치료비 | E32: =SUM(G32:P32) -> 0
C33: 입원일당 | E33: =SUM(G33:P33) -> 0
B34: 심장 | C34: 심혈관 | E34: =SUM(G34:P34) -> 0
C35: 허혈성심장질환 | E35: =SUM(G35:P35) -> 0
C36: 급성심근경색 | E36: =E35+SUM(G36:P36) -> 0
C37: 중대한급성심근경색 | E37: =E36+SUM(G37:P37) -> 0
C38: 수술비 | E38: =SUM(G38:P38) -> 0
C39: 치료비 | E39: =SUM(G39:P39) -> 0
C40: 입원일당 | E40: =SUM(G40:P40) -> 0
B41: 뇌 | C41: 뇌혈관 | E41: =SUM(G41:P41) -> 0
C42: 뇌졸중 | E42: =E41+SUM(G42:P42) -> 0
C43: 뇌출혈 | E43: =E42+SUM(G43:P43) -> 0
C44: 중대한뇌졸중 | E44: =E43+SUM(G44:K44) -> 0
C45: 수술비 | E45: =SUM(G45:P45) -> 0
...

Sheet 통합보장 분석(후)
A1: ='통합보장 분석(전)'!A1:L1 -> VIP 고객님 통합보장 분석
A2: 생년월일 | C2: ="보험나이 "&DATEDIF(EDATE($A$3,-6),$I$4,"y")&"세" -> 보험나이 35세
A3: ='통합보장 분석(전)'!A4:B4 -> 33302 | C3: =EDATE($A$3,6) -> 33486
I4: =TODAY() -> 46207 | T4: 전 | U4: 후 | V4: 해지 | W4: 변경 | X4: 변경/해지
A5: 구 분 | C5: 회 사 명 | E5: Total(전) | F5: → | G5: Total(후) | H5: 증감
C6: 보 험 종 류 | H6: =G6-E6 -> 0
A7: 계 약 | C7: 계 약 일 | H7: =G7-E7 -> 0
C8: 납 입 기 간 | H8: =G8-E8 -> 0
C9: 보 험 기 간 | H9: =G9-E9 -> 0
C10: 월보험료(원) | E10: =SUMIF($J$4:$S$4,$T$4, J10:U10)+SUMIF($J$4:$S$4, $V$4, J10:U10)+SUMIF($J$4:$S$4, $X$4, J10:U10) -> 0 | G10: =E10+SUMIF($J$4:$S$4,$U$4, J10:S10)-SUMIF($J$4:$S$4, $V$4, J10:S10)+SUMIF($J$4:$S$4,$W$4, J10:S10)-SUMIF($J$4:$S$4, $X$4, J10:S10) -> 0 | H10: =G10-E10 -> 0
C11: 갱신 예상보험료 | E11: =SUMIF($J$4:$S$4,$T$4, J11:U11)+SUMIF($J$4:$S$4, $V$4, J11:U11)+SUMIF($J$4:$S$4, $X$4, J11:U11) -> 0 | G11: =E11+SUMIF($J$4:$S$4,$U$4, J11:S11)-SUMIF($J$4:$S$4, $V$4, J11:S11)+SUMIF($J$4:$S$4,$W$4, J11:S11)-SUMIF($J$4:$S$4, $X$4, J11:S11) -> 0 | H11: =G11-E11 -> 0
C12: 총납입보험료 | E12: =SUMIF($J$4:$S$4,$T$4, J12:U12)+SUMIF($J$4:$S$4, $V$4, J12:U12)+SUMIF($J$4:$S$4, $X$4, J12:U12) -> 0 | G12: =E12+SUMIF($J$4:$S$4,$U$4, J12:S12)-SUMIF($J$4:$S$4, $V$4, J12:S12)+SUMIF($J$4:$S$4,$W$4, J12:S12)-SUMIF($J$4:$S$4, $X$4, J12:S12) -> 0 | H12: =G12-E12 -> 0
C13: 납입완료 | E13: =SUMIF($J$4:$S$4,$T$4, J13:U13)+SUMIF($J$4:$S$4, $V$4, J13:U13)+SUMIF($J$4:$S$4, $X$4, J13:U13) -> 0 | G13: =E13+SUMIF($J$4:$S$4,$U$4, J13:S13)-SUMIF($J$4:$S$4, $V$4, J13:S13)+SUMIF($J$4:$S$4,$W$4, J13:S13)-SUMIF($J$4:$S$4, $X$4, J13:S13) -> 0
C14: 납입예정 | E14: =SUMIF($J$4:$S$4,$T$4, J14:U14)+SUMIF($J$4:$S$4, $V$4, J14:U14)+SUMIF($J$4:$S$4, $X$4, J14:U14) -> 0 | G14: =E14+SUMIF($J$4:$S$4,$U$4, J14:S14)-SUMIF($J$4:$S$4, $V$4, J14:S14)+SUMIF($J$4:$S$4,$W$4, J14:S14)-SUMIF($J$4:$S$4, $X$4, J14:S14) -> 0
A15: 실손의료비 | C15: 질병 입원의료비 | E15: =SUMIF($J$4:$S$4,$T$4, J15:U15)+SUMIF($J$4:$S$4, $V$4, J15:U15)+SUMIF($J$4:$S$4, $X$4, J15:U15) -> 0 | G15: =E15+SUMIF($J$4:$S$4,$U$4, J15:S15)-SUMIF($J$4:$S$4, $V$4, J15:S15)+SUMIF($J$4:$S$4,$W$4, J15:S15)-SUMIF($J$4:$S$4, $X$4, J15:S15) -> 0 | H15: =G15-E15 -> 0
C16: 질병 통원의료비 | E16: =SUMIF($J$4:$S$4,$T$4, J16:U16)+SUMIF($J$4:$S$4, $V$4, J16:U16)+SUMIF($J$4:$S$4, $X$4, J16:U16) -> 0 | G16: =E16+SUMIF($J$4:$S$4,$U$4, J16:S16)-SUMIF($J$4:$S$4, $V$4, J16:S16)+SUMIF($J$4:$S$4,$W$4, J16:S16)-SUMIF($J$4:$S$4, $X$4, J16:S16) -> 0 | H16: =G16-E16 -> 0
C17: 상해 입원의료비 | E17: =SUMIF($J$4:$S$4,$T$4, J17:U17)+SUMIF($J$4:$S$4, $V$4, J17:U17)+SUMIF($J$4:$S$4, $X$4, J17:U17) -> 0 | G17: =E17+SUMIF($J$4:$S$4,$U$4, J17:S17)-SUMIF($J$4:$S$4, $V$4, J17:S17)+SUMIF($J$4:$S$4,$W$4, J17:S17)-SUMIF($J$4:$S$4, $X$4, J17:S17) -> 0 | H17: =G17-E17 -> 0
C18: 상해 통원의료비 | E18: =SUMIF($J$4:$S$4,$T$4, J18:U18)+SUMIF($J$4:$S$4, $V$4, J18:U18)+SUMIF($J$4:$S$4, $X$4, J18:U18) -> 0 | G18: =E18+SUMIF($J$4:$S$4,$U$4, J18:S18)-SUMIF($J$4:$S$4, $V$4, J18:S18)+SUMIF($J$4:$S$4,$W$4, J18:S18)-SUMIF($J$4:$S$4, $X$4, J18:S18) -> 0 | H18: =G18-E18 -> 0
A22: 3대 질병 | B22: 암 | C22: 고액암 | E22: =E23+E24+E25+E26+SUMIF($J$4:$S$4,$T$4, J22:U22)+SUMIF($J$4:$S$4, $V$4, J22:U22)+SUMIF($J$4:$S$4, $X$4, J22:U22) -> 0 | F22: → | G22: =E22+SUMIF($J$4:$S$4,$U$4, J22:S22)+SUMIF($J$4:$S$4,$U$4, J23:S23)-SUMIF($J$4:$S$4, $V$4, J22:S22)-SUMIF($J$4:$S$4, $V$4, J23:S23)+SUMIF($J$4:$S$4,$W$4, J22:S22)+SUMIF($J$4:$S$4,$W$4, J23:S23)+SUMIF($J$4:$S$4,$U$4, J24:S24)-SUMIF($J$4:$S$4, $V$4, J24:S24)+SUMIF($J$4:$S$4,$W$4, J24:S24)+SUMIF($J$4:$S$4,$U$4, J25:S25)-SUMIF($J$4:$S$4, $V$4, J25:S25)+SUMIF($J$4:$S$4,$W$4, J25:S25)+SUMIF($J$4:$S$4,$U$4, J26:S26)-SUMIF($J$4:$S$4, $V$4, J26:S26)+SUMIF($J$4:$S$4,$W$4, J26:S26)-SUMIF($J$4:$S$4, $X$4, J22:S22)-SUMIF($J$4:$S$4, $X$4, J23:S23)-SUMIF($J$4:$S$4, $X$4, J24:S24)-SUMIF($J$4:$S$4, $X$4, J25:S25)-SUMIF($J$4:$S$4, $X$4, J26:S26) -> 0 | H22: =G22-E22 -> 0
C23: 일반암 | E23: =SUMIF($J$4:$S$4,$T$4, J23:U23)+SUMIF($J$4:$S$4, $V$4, J23:U23)+SUMIF($J$4:$S$4, $X$4, J23:U23) -> 0 | G23: =E23+SUMIF($J$4:$S$4,$U$4, J23:S23)-SUMIF($J$4:$S$4, $V$4, J23:S23)+SUMIF($J$4:$S$4,$W$4, J23:S23)-SUMIF($J$4:$S$4, $X$4, J23:S23) -> 0 | H23: =G23-E23 -> 0
C24: 일반암(소액·대장점막제외) | E24: =SUMIF($J$4:$S$4,$T$4, J24:U24)+SUMIF($J$4:$S$4, $V$4, J24:U24)+SUMIF($J$4:$S$4, $X$4, J24:U24) -> 0 | G24: =E24+SUMIF($J$4:$S$4,$U$4, J24:S24)-SUMIF($J$4:$S$4, $V$4, J24:S24)+SUMIF($J$4:$S$4,$W$4, J24:S24)-SUMIF($J$4:$S$4, $X$4, J24:S24) -> 0 | H24: =G24-E24 -> 0
C25: 일반암(소액암제외) | E25: =SUMIF($J$4:$S$4,$T$4, J25:U25)+SUMIF($J$4:$S$4, $V$4, J25:U25)+SUMIF($J$4:$S$4, $X$4, J25:U25) -> 0 | G25: =E25+SUMIF($J$4:$S$4,$U$4, J25:S25)-SUMIF($J$4:$S$4, $V$4, J25:S25)+SUMIF($J$4:$S$4,$W$4, J25:S25)-SUMIF($J$4:$S$4, $X$4, J25:S25) -> 0 | H25: =G25-E25 -> 0
C26: 중대한암 | E26: =SUMIF($J$4:$S$4,$T$4, J26:U26)+SUMIF($J$4:$S$4, $V$4, J26:U26)+SUMIF($J$4:$S$4, $X$4, J26:U26) -> 0 | G26: =E26+SUMIF($J$4:$S$4,$U$4, J26:S26)-SUMIF($J$4:$S$4, $V$4, J26:S26)+SUMIF($J$4:$S$4,$W$4, J26:S26)-SUMIF($J$4:$S$4, $X$4, J26:S26) -> 0 | H26: =G26-E26 -> 0
C27: 소액암(생식기암) | E27: =SUMIF($J$4:$S$4,$T$4, J27:U27)+SUMIF($J$4:$S$4, $V$4, J27:U27)+SUMIF($J$4:$S$4, $X$4, J27:U27) -> 0 | G27: =E27+SUMIF($J$4:$S$4,$U$4, J27:S27)-SUMIF($J$4:$S$4, $V$4, J27:S27)+SUMIF($J$4:$S$4,$W$4, J27:S27)-SUMIF($J$4:$S$4, $X$4, J27:S27) -> 0 | H27: =G27-E27 -> 0
C28: 소액암 | E28: =SUMIF($J$4:$S$4,$T$4, J28:U28)+SUMIF($J$4:$S$4, $V$4, J28:U28)+SUMIF($J$4:$S$4, $X$4, J28:U28) -> 0 | G28: =E28+SUMIF($J$4:$S$4,$U$4, J28:S28)-SUMIF($J$4:$S$4, $V$4, J28:S28)+SUMIF($J$4:$S$4,$W$4, J28:S28)-SUMIF($J$4:$S$4, $X$4, J28:S28) -> 0 | H28: =G28-E28 -> 0
C29: 수술비 | E29: =SUMIF($J$4:$S$4,$T$4, J29:U29)+SUMIF($J$4:$S$4, $V$4, J29:U29)+SUMIF($J$4:$S$4, $X$4, J29:U29) -> 0 | G29: =E29+SUMIF($J$4:$S$4,$U$4, J29:S29)-SUMIF($J$4:$S$4, $V$4, J29:S29)+SUMIF($J$4:$S$4,$W$4, J29:S29)-SUMIF($J$4:$S$4, $X$4, J29:S29) -> 0 | H29: =G29-E29 -> 0
C30: 항암치료/표적/중입자 | E30: =SUMIF($J$4:$S$4,$T$4, J30:U30)+SUMIF($J$4:$S$4, $V$4, J30:U30)+SUMIF($J$4:$S$4, $X$4, J30:U30) -> 0 | G30: =E30+SUMIF($J$4:$S$4,$U$4, J30:S30)-SUMIF($J$4:$S$4, $V$4, J30:S30)+SUMIF($J$4:$S$4,$W$4, J30:S30)-SUMIF($J$4:$S$4, $X$4, J30:S30) -> 0 | H30: =G30-E30 -> 0
C31: 암주요치료비 | E31: =SUMIF($J$4:$S$4,$T$4, J31:U31)+SUMIF($J$4:$S$4, $V$4, J31:U31)+SUMIF($J$4:$S$4, $X$4, J31:U31) -> 0 | G31: =E31+SUMIF($J$4:$S$4,$U$4, J31:S31)-SUMIF($J$4:$S$4, $V$4, J31:S31)+SUMIF($J$4:$S$4,$W$4, J31:S31)-SUMIF($J$4:$S$4, $X$4, J31:S31) -> 0 | H31: =G31-E31 -> 0
C32: 입원일당 | E32: =SUMIF($J$4:$S$4,$T$4, J32:U32)+SUMIF($J$4:$S$4, $V$4, J32:U32)+SUMIF($J$4:$S$4, $X$4, J32:U32) -> 0 | G32: =E32+SUMIF($J$4:$S$4,$U$4, J32:S32)-SUMIF($J$4:$S$4, $V$4, J32:S32)+SUMIF($J$4:$S$4,$W$4, J32:S32)-SUMIF($J$4:$S$4, $X$4, J32:S32) -> 0 | H32: =G32-E32 -> 0
B33: 심장 | C33: 심혈관 | E33: =SUMIF($J$4:$S$4,$T$4, J33:U33)+SUMIF($J$4:$S$4, $V$4, J33:U33)+SUMIF($J$4:$S$4, $X$4, J33:U33) -> 0 | G33: =E33+SUMIF($J$4:$S$4,$U$4, J33:S33)-SUMIF($J$4:$S$4, $V$4, J33:S33)+SUMIF($J$4:$S$4,$W$4, J33:S33)-SUMIF($J$4:$S$4, $X$4, J33:S33) -> 0 | H33: =G33-E33 -> 0
C34: 허혈성심장질환 | E34: =SUMIF($J$4:$S$4,$T$4, J34:U34)+SUMIF($J$4:$S$4, $V$4, J34:U34)+SUMIF($J$4:$S$4, $X$4, J34:U34) -> 0 | G34: =E34+SUMIF($J$4:$S$4,$U$4, J34:S34)-SUMIF($J$4:$S$4, $V$4, J34:S34)+SUMIF($J$4:$S$4,$W$4, J34:S34)-SUMIF($J$4:$S$4, $X$4, J34:S34) -> 0 | H34: =G34-E34 -> 0
C35: 급성심근경색 | E35: =E34+SUMIF($J$4:$S$4,$T$4, J35:U35)+SUMIF($J$4:$S$4, $V$4, J35:U35)+SUMIF($J$4:$S$4, $X$4, J35:U35) -> 0 | G35: =E35+SUMIF($J$4:$S$4,$U$4, J35:S35)+SUMIF($J$4:$S$4,$U$4, J34:S34)-SUMIF($J$4:$S$4, $V$4, J35:S35)-SUMIF($J$4:$S$4, $V$4, J34:S34)+SUMIF($J$4:$S$4,$W$4, J35:S35)+SUMIF($J$4:$S$4,$W$4, J34:S34)-SUMIF($J$4:$S$4, $X$4, J35:S35)-SUMIF($J$4:$S$4, $X$4, J34:S34) -> 0 | H35: =G35-E35 -> 0
C36: 중대한급성심근경색 | E36: =E35+SUMIF($J$4:$S$4,$T$4, J36:U36)+SUMIF($J$4:$S$4, $V$4, J36:U36)+SUMIF($J$4:$S$4, $X$4, J36:U36) -> 0 | G36: =E36+SUMIF($J$4:$S$4,$U$4, J36:S36)+SUMIF($J$4:$S$4,$U$4, J35:S35)+SUMIF($J$4:$S$4,$U$4, J34:S34)-SUMIF($J$4:$S$4, $V$4, J36:S36)-SUMIF($J$4:$S$4, $V$4, J35:S35)-SUMIF($J$4:$S$4, $V$4, J34:S34)+SUMIF($J$4:$S$4,$W$4, J36:S36)+SUMIF($J$4:$S$4,$W$4, J35:S35)+SUMIF($J$4:$S$4,$W$4, J34:S34)-SUMIF($J$4:$S$4, $X$4, J36:S36)-SUMIF($J$4:$S$4, $X$4, J35:S35)-SUMIF($J$4:$S$4, $X$4, J34:S34) -> 0 | H36: =G36-E36 -> 0
C37: 수술비 | E37: =SUMIF($J$4:$S$4,$T$4, J37:U37)+SUMIF($J$4:$S$4, $V$4, J37:U37)+SUMIF($J$4:$S$4, $X$4, J37:U37) -> 0 | G37: =E37+SUMIF($J$4:$S$4,$U$4, J37:S37)-SUMIF($J$4:$S$4, $V$4, J37:S37)+SUMIF($J$4:$S$4,$W$4, J37:S37)-SUMIF($J$4:$S$4, $X$4, J37:S37) -> 0 | H37: =G37-E37 -> 0
C38: 치료비 | E38: =SUMIF($J$4:$S$4,$T$4, J38:U38)+SUMIF($J$4:$S$4, $V$4, J38:U38)+SUMIF($J$4:$S$4, $X$4, J38:U38) -> 0 | G38: =E38+SUMIF($J$4:$S$4,$U$4, J38:S38)-SUMIF($J$4:$S$4, $V$4, J38:S38)+SUMIF($J$4:$S$4,$W$4, J38:S38)-SUMIF($J$4:$S$4, $X$4, J38:S38) -> 0 | H38: =G38-E38 -> 0
C39: 입원일당 | E39: =SUMIF($J$4:$S$4,$T$4, J39:U39)+SUMIF($J$4:$S$4, $V$4, J39:U39)+SUMIF($J$4:$S$4, $X$4, J39:U39) -> 0 | G39: =E39+SUMIF($J$4:$S$4,$U$4, J39:S39)-SUMIF($J$4:$S$4, $V$4, J39:S39)+SUMIF($J$4:$S$4,$W$4, J39:S39)-SUMIF($J$4:$S$4, $X$4, J39:S39) -> 0 | H39: =G39-E39 -> 0
B40: 뇌 | C40: 뇌혈관 | E40: =SUMIF($J$4:$S$4,$T$4, J40:U40)+SUMIF($J$4:$S$4, $V$4, J40:U40)+SUMIF($J$4:$S$4, $X$4, J40:U40) -> 0 | G40: =E40+SUMIF($J$4:$S$4,$U$4, J40:S40)-SUMIF($J$4:$S$4, $V$4, J40:S40)+SUMIF($J$4:$S$4,$W$4, J40:S40)-SUMIF($J$4:$S$4, $X$4, J40:S40) -> 0 | H40: =G40-E40 -> 0
C41: 뇌졸중 | E41: =E40+SUMIF($J$4:$S$4,$T$4, J41:U41)+SUMIF($J$4:$S$4, $V$4, J41:U41)+SUMIF($J$4:$S$4, $X$4, J41:U41) -> 0 | G41: =E41+SUMIF($J$4:$S$4,$U$4, J41:S41)+SUMIF($J$4:$S$4,$U$4, J40:S40)-SUMIF($J$4:$S$4, $V$4, J41:S41)-SUMIF($J$4:$S$4, $V$4, J40:S40)+SUMIF($J$4:$S$4,$W$4, J41:S41)+SUMIF($J$4:$S$4,$W$4, J40:S40)-SUMIF($J$4:$S$4, $X$4, J41:S41)-SUMIF($J$4:$S$4, $X$4, J40:S40) -> 0 | H41: =G41-E41 -> 0
C42: 뇌출혈 | E42: =E41+SUMIF($J$4:$S$4,$T$4, J42:U42)+SUMIF($J$4:$S$4, $V$4, J42:U42)+SUMIF($J$4:$S$4, $X$4, J42:U42) -> 0 | G42: =E42+SUMIF($J$4:$S$4,$U$4, J42:S42)+SUMIF($J$4:$S$4,$U$4, J41:S41)+SUMIF($J$4:$S$4,$U$4, J40:S40)-SUMIF($J$4:$S$4, $V$4, J42:S42)-SUMIF($J$4:$S$4, $V$4, J41:S41)-SUMIF($J$4:$S$4, $V$4, J40:S40)+SUMIF($J$4:$S$4,$W$4, J42:S42)+SUMIF($J$4:$S$4,$W$4, J41:S41)+SUMIF($J$4:$S$4,$W$4, J40:S40)-SUMIF($J$4:$S$4, $X$4, J42:S42)-SUMIF($J$4:$S$4, $X$4, J41:S41)-SUMIF($J$4:$S$4, $X$4, J40:S40) -> 0 | H42: =G42-E42 -> 0
C43: 중대한뇌졸중 | E43: =E42+SUMIF($J$4:$S$4,$T$4, J43:U43)+SUMIF($J$4:$S$4, $V$4, J43:U43)+SUMIF($J$4:$S$4, $X$4, J43:U43) -> 0 | G43: =E43+SUMIF($J$4:$S$4,$U$4, J43:S43)+SUMIF($J$4:$S$4,$U$4, J42:S42)+SUMIF($J$4:$S$4,$U$4, J41:S41)+SUMIF($J$4:$S$4,$U$4, J40:S40)-SUMIF($J$4:$S$4, $V$4, J43:S43)-SUMIF($J$4:$S$4, $V$4, J42:S42)-SUMIF($J$4:$S$4, $V$4, J41:S41)-SUMIF($J$4:$S$4, $V$4, J40:S40)+SUMIF($J$4:$S$4,$W$4, J43:S43)+SUMIF($J$4:$S$4,$W$4, J42:S42)+SUMIF($J$4:$S$4,$W$4, J41:S41)+SUMIF($J$4:$S$4,$W$4, J40:S40)-SUMIF($J$4:$S$4, $X$4, J43:S43)-SUMIF($J$4:$S$4, $X$4, J42:S42)-SUMIF($J$4:$S$4, $X$4, J41:S41)-SUMIF($J$4:$S$4, $X$4, J40:S40) -> 0 | H43: =G43-E43 -> 0
...

Sheet 보장분석 컨설팅
A2: VIP고객님의 보장분석 컨설팅
A4: ※ point
A5: 1. 월/전체 보험료 절감
A6: 2. 3대진단비/수술비 보장확대
A7: 1) 기존: 암진단비 1.6억(갱신포함 )/ 뇌혈관 1천(갱신) / 허혈성 1천(갱신) / 2대수술비 1천(갱신)
A8: 2) 변경: 암진단비 1.5억(비갱신) / 뇌혈관 2천 / 허혈성 2천 / 2대수술비 각 2천
A9: 3. 수술비 보장 확대
A10: 1) 기존: 질병수술비 2십 / 질병종수술비 6백 / 상해종수술비 16백
A11: 2) 변경: 질병수술비 3십 / 질병종수술비 11백 / 상해종수술비 21백
A12: 4. 치매보험의 패러다임 변경 및 사망시 보험금 지급 상품으로 변경
A13: 5. 표적항암 1천 + 항암방사선 3백 + 항암약물 3백 추가
E14: 컨설팅전 | F14: 컨설팅후
A16: 월 보험료 | E16: ='통합보장 분석(후)'!E10 -> 0 | F16: ='통합보장 분석(후)'!G10 -> 0 | G16: =F16-E16 -> 0
A17: 갱신 예상 전체보험료 | E17: ='통합보장 분석(후)'!E11 -> 0 | F17: ='통합보장 분석(후)'!G11 -> 0
A18: 전체 보험료 | E18: ='통합보장 분석(후)'!E12 -> 0 | F18: ='통합보장 분석(후)'!G12 -> 0
A19: 납입완료 | E19: ='통합보장 분석(후)'!E13 -> 0 | F19: ='통합보장 분석(후)'!G13 -> 0
A20: ㅗ | E20: ='통합보장 분석(후)'!E14 -> 0 | F20: ='통합보장 분석(후)'!G14 -> 0
A21: 갱신 예상 절감 금액 | E21: =F17-E17 -> 0
A22: 절감 금액 | E22: =F18-E18 -> 0
A24: 3대 질병 | B24: 암 | C24: 고액암 | E24: ='통합보장 분석(후)'!E22 -> 0 | F24: ='통합보장 분석(후)'!G22 -> 0 | G24: =F24-E24 -> 0
C25: 일반암 | E25: ='통합보장 분석(후)'!E23 -> 0 | F25: ='통합보장 분석(후)'!G23 -> 0 | G25: =F25-E25 -> 0
C26: 일반암(소액·대장점막제외) | E26: ='통합보장 분석(후)'!E24 -> 0 | F26: ='통합보장 분석(후)'!G24 -> 0 | G26: =F26-E26 -> 0
C27: 일반암(소액암제외) | E27: ='통합보장 분석(후)'!E25 -> 0 | F27: ='통합보장 분석(후)'!G25 -> 0 | G27: =F27-E27 -> 0
C28: 중대한암 | E28: ='통합보장 분석(후)'!E26 -> 0 | F28: ='통합보장 분석(후)'!G26 -> 0 | G28: =F28-E28 -> 0
C29: 소액암(생식기암) | E29: ='통합보장 분석(후)'!E27 -> 0 | F29: ='통합보장 분석(후)'!G27 -> 0 | G29: =F29-E29 -> 0
C30: 소액암 | E30: ='통합보장 분석(후)'!E28 -> 0 | F30: ='통합보장 분석(후)'!G28 -> 0 | G30: =F30-E30 -> 0
C31: 수술비 | E31: ='통합보장 분석(후)'!E29 -> 0 | F31: ='통합보장 분석(후)'!G29 -> 0 | G31: =F31-E31 -> 0
C32: 항암치료/표적항암 | E32: ='통합보장 분석(후)'!E30 -> 0 | F32: ='통합보장 분석(후)'!G30 -> 0 | G32: =F32-E32 -> 0
C33: 암주요치료비 | E33: ='통합보장 분석(후)'!E31 -> 0 | F33: ='통합보장 분석(후)'!G31 -> 0
C34: 입원일당 | E34: ='통합보장 분석(후)'!E32 -> 0 | F34: ='통합보장 분석(후)'!G32 -> 0 | G34: =F34-E34 -> 0
B35: 심장 | C35: 심혈관 | E35: ='통합보장 분석(후)'!E33 -> 0 | F35: ='통합보장 분석(후)'!G33 -> 0 | G35: =F35-E35 -> 0
C36: 허혈성심장질환 | E36: ='통합보장 분석(후)'!E34 -> 0 | F36: ='통합보장 분석(후)'!G34 -> 0 | G36: =F36-E36 -> 0
C37: 급성심근경색 | E37: ='통합보장 분석(후)'!E35 -> 0 | F37: ='통합보장 분석(후)'!G35 -> 0 | G37: =F37-E37 -> 0
C38: 중대한급성심근경색 | E38: ='통합보장 분석(후)'!E36 -> 0 | F38: ='통합보장 분석(후)'!G36 -> 0 | G38: =F38-E38 -> 0
C39: 수술비 | E39: ='통합보장 분석(후)'!E37 -> 0 | F39: ='통합보장 분석(후)'!G37 -> 0 | G39: =F39-E39 -> 0
C40: 치료비 | E40: ='통합보장 분석(후)'!E38 -> 0
C41: 입원일당 | E41: ='통합보장 분석(후)'!E39 -> 0 | F41: ='통합보장 분석(후)'!G39 -> 0 | G41: =F41-E41 -> 0
B42: 뇌 | C42: 뇌혈관 | E42: ='통합보장 분석(후)'!E40 -> 0 | F42: ='통합보장 분석(후)'!G40 -> 0 | G42: =F42-E42 -> 0
C43: 뇌졸중 | E43: ='통합보장 분석(후)'!E41 -> 0 | F43: ='통합보장 분석(후)'!G41 -> 0 | G43: =F43-E43 -> 0
C44: 뇌출혈 | E44: ='통합보장 분석(후)'!E42 -> 0 | F44: ='통합보장 분석(후)'!G42 -> 0 | G44: =F44-E44 -> 0
...

Sheet 태아보험 보험료 비교(100세)
A1: VIP 고객님 태아보험 컨설팅
B8: ✔ 단독실손
A9: - | B9: 출생 전 : | C9: 14210
A10: - | B10: 출생 후 : | C10: 21560
A11: ▷태아실손은 출생시점이 제일 비싸고 이후 갱신시 계속 저렴해집니다.
B13: ✔ 어린이보험 | D13: 100세만기
A14: - | B14: 출생 전 : | C14: 7289
A15: - | B15: 출생 후 : | C15: 89010
B17: ✔ 어린이보험 | D17: 20년만기 | E17: 해지 예정
A18: - | B18: 출생 전 : | C18: 49320
A19: - | B19: 출생 후 : | C19: 28930 | D19: (1년이내)
A20: - | B20: 출생 후 : | C20: 14245 | D20: (1년이후)
A22: ▷모든 설계 내용은 남아 기준으로 설계되있어 여아인 경우 보험료가 인하됩니다.
B25: ▣ 출생 전 합계 : | D25: =C9+C14+C18 -> 70819 | G25: 실손 제외 합계
B26: ▣ 출생 후 합계 : | D26: =C10+C15+C19 -> 139500 | E26: (1년이내) | F26: → | G26: =D26-C10 -> 117940
D27: =C10+C15+C20 -> 124815 | E27: (1년이후) | G27: =D27-C10 -> 103255
D28: =C10+C15 -> 110570 | E28: (3살이후) | G28: =D28-C10 -> 89010
A29: ＊위 보험료는 실손 인하를 고려하지 않은 보험료로 실제 보험료는 더 저렴합니다.
A31: ▷실손보험료 점점 줄어듦
A32: ▷여아인 경우 보험료 줄어듦
A33: ▷태아특약 1년 만기 후 보험료 줄어듦
A34: ▷3살 이후 입원일당 삭제시 보험료 줄어듦
A36: ▶출생시점이 제일 비싸고 이후 계속 보험료가 저렴해집니다^^

Sheet 태아보험 보험료 비교(30세)
A1: VIP 고객님 태아보험 컨설팅
B8: ✔ 단독실손
A9: - | B9: 출생 전 : | C9: 14210
A10: - | B10: 출생 후 : | C10: 21560
A11: ▷태아실손은 출생시점이 제일 비싸고 이후 갱신시 계속 저렴해집니다.
B13: ✔ 어린이보험 | D13: 100세만기
A14: - | B14: 출생 전 :
A15: - | B15: 출생 후 :
B17: ✔ 어린이보험 | D17: 30세만기
A18: - | B18: 출생 전 : | C18: 72440
A19: - | B19: 출생 후 : | C19: 64950 | D19: (1년 이내)
A20: - | B20: 출생 후 : | C20: 52024 | D20: (1년 이후)
A21: - | B21: 출생 후 : | C21: 37955 | D21: (3살 이후)
A23: ▷모든 설계 내용은 남아 기준으로 설계되있어 여아인 경우 보험료가 인하됩니다.
B26: ▣ 출생 전 합계 : | D26: =C9+C14+C18 -> 86650 | G26: 실손 제외 합계
B27: ▣ 출생 후 합계 : | D27: =C10+C15+C19 -> 86510 | E27: (1년이내) | F27: → | G27: =D27-C10 -> 64950
D28: =C10+C15+C20 -> 73584 | E28: (1년이후) | G28: =D28-C10 -> 52024
D29: =C10+C21 -> 59515 | E29: (3살이후) | G29: =D29-C10 -> 37955
A31: ＊위 보험료는 실손 인하를 고려하지 않은 보험료로 실제 보험료는 더 저렴합니다.
A33: ▷실손보험료 점점 줄어듦
A34: ▷여아인 경우 보험료 줄어듦
A35: ▷태아특약 1년 만기 후 보험료 줄어듦
A36: ▷3살 이후 입원일당 삭제시 보험료 줄어듦
A38: ▶출생시점이 제일 비싸고 이후 계속 보험료가 저렴해집니다^^

Sheet 태아보험 보험기간
B2: 태아보험의 보험기간
B12: 장점 | G12: 장점
B14: 보험료 저렴 | G14: 한번 가입으로 100세까지 보장
G15: - 좋은 보장들을 끝까지 유지
G16: - 무해지 (30%할인) 적용 가능
B18: 단점 | G18: 단점
B20: 30세 시점에 보험 재가입 | G20: 보험료 비쌈
B21: - 30세부터 다시 20년 납입(총 40년납) | G21: - 30세 대비 3배 이상 비쌈 무해지 (30%할인) 적용시 실제 2배 정도 차이
B22: - 30세 나이로 20년(태아 대비 보험료 2배 이상↑)
B24: 과거 병력에 따라 재가입 불가
B25: - 계약전환제도 기능(30세 시점 100세 만기로 변경)
B26: - 30세부터 다시 20년 납입(총 40년납)
B27: - 무해지 (30%할인) 불가능
B32: 각 가정의 경제상황, 여력에 따라 30세 또는 100세 만기 결정
B34: 무해지환급형(표준형 대비 보험료 30%할인) 으로 적용시 30세 만기와 100세 만기의 보험료 차이가 크지 않아 납입여력이 가능한 경우 100세 만기 권고 (30세 만기는 표준형/무해지환급형不)

Sheet 1건 보험료비교(100세, 90세, 납기별)
A1: VIP고객님 컨설팅
A2: DB손해 어린이 | I2: 합계보험료
B3: 100세 만기 | C3: 총납입보험료 | D3: 비고 | E3: 합계보험료 | F3: 90세 만기 | G3: 총납입보험료 | H3: 비고 | K3: D3, H3 '비고' 숨기기 있음
A4: 20년납 | B4: 78970 | C4: =B4*240 -> 18952800 | D4: 유사암 700만원 | E4: =B4+$B$9 -> 94827 | F4: 112560 | G4: =F4*240 -> 27014400 | H4: 유사암 700만원 | I4: =F4+$B$9 -> 128417
A5: 25년납 | B5: 69000 | C5: =B5*300 -> 20700000 | D5: 유사암 600만원 | E5: =B5+$B$9 -> 84857 | F5: 99770 | G5: =F5*300 -> 29931000 | H5: 유사암 700만원 | I5: =F5+$B$9 -> 115627
A6: 30년납 | B6: 62510 | C6: =B6*360 -> 22503600 | D6: 유사암 600만원 | E6: =B6+$B$9 -> 78367 | F6: 91770 | G6: =F6*360 -> 33037200 | H6: 유사암 600만원 | I6: =F6+$B$9 -> 107627
A8: 기존 계약사항
A9: 한화 실손 | B9: 15857

Sheet 2건 보험료비교(납기별)
A1: VIP고객님 컨설팅
B2: 흥국 어린이 | E2: 농협 어린이 | H2: 합계보험료
B3: 보험료 | C3: 총납입보험료 | D3: 비고 | E3: 보험료 | F3: 총납입보험료 | G3: 비고 | J3: E3, G3 '비고' 숨기기 있음
A4: 20년납 | B4: 91270 | C4: =B4*240 -> 21904800 | E4: 50000 | F4: =E4*240 -> 12000000 | H4: =B9+B10+B4+E4 -> 190916
A5: 25년납 | B5: 81700 | C5: =B5*300 -> 24510000 | E5: 42000 | F5: =E5*300 -> 12600000 | H5: =B9+B10+B5+E5 -> 173346
A6: 30년납 | B6: 77530 | C6: =B6*360 -> 27910800 | E6: 38000 | F6: =E6*360 -> 13680000 | H6: =B9+B10+B6+E6 -> 165176
A8: 기존 계약사항
A9: A보험 | B9: 14181
A10: B보험 | B10: 35465
A11: C보험
A12: D보험

Sheet 2건 보험료비교(납기별, 100세, 90세)
A1: VIP고객님 컨설팅
B2: 흥국 어린이 | G2: 농협 어린이 | L2: 합계보험료 100세 만기 | M2: 합계보험료 90세 만기
B3: 100세 만기 | C3: 총납입보험료 | D3: 90세 만기 | E3: 총납입보험료 | F3: 비고 | G3: 100세 만기 | H3: 총납입보험료 | I3: 90세만기 | J3: 총납입보험료 | K3: 비고 | O3: F4, K4 '비고' 숨기기 있음
A4: 20년납 | B4: 100000 | C4: =B4*240 -> 24000000 | D4: 95000 | E4: =D4*240 -> 22800000 | G4: 41731 | H4: =G4*240 -> 10015440 | I4: 41731 | J4: =I4*240 -> 10015440 | L4: =$B$9+$B$10+$B$11+$B$12+$B$13+B4+G4 -> 141731 | M4: =$B$9+$B$10+$B$11+$B$12+$B$13+D4+I4 -> 136731
A5: 25년납 | B5: 90000 | C5: =B5*300 -> 27000000 | D5: 85000 | E5: =D5*300 -> 25500000 | G5: 33321 | H5: =G5*300 -> 9996300 | I5: 33321 | J5: =I5*300 -> 9996300 | L5: =$B$9+$B$10+$B$11+$B$12+$B$13+B5+G5 -> 123321 | M5: =$B$9+$B$10+$B$11+$B$12+$B$13+D5+I5 -> 118321
A6: 30년납 | B6: 80000 | C6: =B6*360 -> 28800000 | D6: 75000 | E6: =D6*360 -> 27000000 | G6: 27949 | H6: =G6*360 -> 10061640 | I6: 27949 | J6: =I6*360 -> 10061640 | L6: =$B$9+$B$10+$B$11+$B$12+$B$13+B6+G6 -> 107949 | M6: =$B$9+$B$10+$B$11+$B$12+$B$13+D6+I6 -> 102949
A8: 기존 계약사항
A9: A보험
A10: B보험
A11: C보험
A12: D보험
A13: E보험
